
Due to MODULEPATH changes, the following have been reloaded:
  1) Python/3.12.3-GCCcore-13.3.0


Due to MODULEPATH changes, the following have been reloaded:
  1) CUDA/12.4.0

master_addr is only used for static rdzv_backend and when rdzv_endpoint is not specified.
Traceback (most recent call last):
  File "/home/s33zganj/pytorch/lib/python3.10/site-packages/huggingface_hub/utils/_errors.py", line 304, in hf_raise_for_status
    response.raise_for_status()
  File "/home/s33zganj/pytorch/lib/python3.10/site-packages/requests/models.py", line 1024, in raise_for_status
    raise HTTPError(http_error_msg, response=self)
requests.exceptions.HTTPError: 401 Client Error: Unauthorized for url: https://huggingface.co/meta-llama/Meta-Llama-3-8B-Instruct/resolve/main/config.json

The above exception was the direct cause of the following exception:

Traceback (most recent call last):
  File "/home/s33zganj/pytorch/lib/python3.10/site-packages/transformers/utils/hub.py", line 402, in cached_file
    resolved_file = hf_hub_download(
  File "/home/s33zganj/pytorch/lib/python3.10/site-packages/huggingface_hub/utils/_deprecation.py", line 101, in inner_f
    return f(*args, **kwargs)
  File "/home/s33zganj/pytorch/lib/python3.10/site-packages/huggingface_hub/utils/_validators.py", line 114, in _inner_fn
    return fn(*args, **kwargs)
  File "/home/s33zganj/pytorch/lib/python3.10/site-packages/huggingface_hub/file_download.py", line 1240, in hf_hub_download
    return _hf_hub_download_to_cache_dir(
  File "/home/s33zganj/pytorch/lib/python3.10/site-packages/huggingface_hub/file_download.py", line 1347, in _hf_hub_download_to_cache_dir
    _raise_on_head_call_error(head_call_error, force_download, local_files_only)
  File "/home/s33zganj/pytorch/lib/python3.10/site-packages/huggingface_hub/file_download.py", line 1854, in _raise_on_head_call_error
    raise head_call_error
  File "/home/s33zganj/pytorch/lib/python3.10/site-packages/huggingface_hub/file_download.py", line 1751, in _get_metadata_or_catch_error
    metadata = get_hf_file_metadata(
  File "/home/s33zganj/pytorch/lib/python3.10/site-packages/huggingface_hub/utils/_validators.py", line 114, in _inner_fn
    return fn(*args, **kwargs)
  File "/home/s33zganj/pytorch/lib/python3.10/site-packages/huggingface_hub/file_download.py", line 1673, in get_hf_file_metadata
    r = _request_wrapper(
  File "/home/s33zganj/pytorch/lib/python3.10/site-packages/huggingface_hub/file_download.py", line 376, in _request_wrapper
    response = _request_wrapper(
  File "/home/s33zganj/pytorch/lib/python3.10/site-packages/huggingface_hub/file_download.py", line 400, in _request_wrapper
    hf_raise_for_status(response)
  File "/home/s33zganj/pytorch/lib/python3.10/site-packages/huggingface_hub/utils/_errors.py", line 321, in hf_raise_for_status
    raise GatedRepoError(message, response) from e
huggingface_hub.utils._errors.GatedRepoError: 401 Client Error. (Request ID: Root=1-66e8310b-2eb6c742495838c72841ab8f;16cdae4a-59ee-43cd-97c2-5bd04c215dd4)

Cannot access gated repo for url https://huggingface.co/meta-llama/Meta-Llama-3-8B-Instruct/resolve/main/config.json.
Access to model meta-llama/Meta-Llama-3-8B-Instruct is restricted. You must have access to it and be authenticated to access it. Please log in.

The above exception was the direct cause of the following exception:

Traceback (most recent call last):
  File "/home/s33zganj/LLaMA_SOTOPIA/pipeline.py", line 66, in <module>
    model = AutoModelForCausalLM.from_pretrained(MODEL_NAME, device_map="auto")
  File "/home/s33zganj/pytorch/lib/python3.10/site-packages/transformers/models/auto/auto_factory.py", line 524, in from_pretrained
    config, kwargs = AutoConfig.from_pretrained(
  File "/home/s33zganj/pytorch/lib/python3.10/site-packages/transformers/models/auto/configuration_auto.py", line 976, in from_pretrained
    config_dict, unused_kwargs = PretrainedConfig.get_config_dict(pretrained_model_name_or_path, **kwargs)
  File "/home/s33zganj/pytorch/lib/python3.10/site-packages/transformers/configuration_utils.py", line 632, in get_config_dict
    config_dict, kwargs = cls._get_config_dict(pretrained_model_name_or_path, **kwargs)
  File "/home/s33zganj/pytorch/lib/python3.10/site-packages/transformers/configuration_utils.py", line 689, in _get_config_dict
    resolved_config_file = cached_file(
  File "/home/s33zganj/pytorch/lib/python3.10/site-packages/transformers/utils/hub.py", line 420, in cached_file
    raise EnvironmentError(
OSError: You are trying to access a gated repo.
Make sure to have access to it at https://huggingface.co/meta-llama/Meta-Llama-3-8B-Instruct.
401 Client Error. (Request ID: Root=1-66e8310b-2eb6c742495838c72841ab8f;16cdae4a-59ee-43cd-97c2-5bd04c215dd4)

Cannot access gated repo for url https://huggingface.co/meta-llama/Meta-Llama-3-8B-Instruct/resolve/main/config.json.
Access to model meta-llama/Meta-Llama-3-8B-Instruct is restricted. You must have access to it and be authenticated to access it. Please log in.
ERROR:torch.distributed.elastic.multiprocessing.api:failed (exitcode: 1) local_rank: 0 (pid: 2285761) of binary: /home/s33zganj/pytorch/bin/python
Traceback (most recent call last):
  File "/home/s33zganj/pytorch/bin/torchrun", line 8, in <module>
    sys.exit(main())
  File "/home/s33zganj/pytorch/lib/python3.10/site-packages/torch/distributed/elastic/multiprocessing/errors/__init__.py", line 346, in wrapper
    return f(*args, **kwargs)
  File "/home/s33zganj/pytorch/lib/python3.10/site-packages/torch/distributed/run.py", line 794, in main
    run(args)
  File "/home/s33zganj/pytorch/lib/python3.10/site-packages/torch/distributed/run.py", line 785, in run
    elastic_launch(
  File "/home/s33zganj/pytorch/lib/python3.10/site-packages/torch/distributed/launcher/api.py", line 134, in __call__
    return launch_agent(self._config, self._entrypoint, list(args))
  File "/home/s33zganj/pytorch/lib/python3.10/site-packages/torch/distributed/launcher/api.py", line 250, in launch_agent
    raise ChildFailedError(
torch.distributed.elastic.multiprocessing.errors.ChildFailedError: 
============================================================
/home/s33zganj/LLaMA_SOTOPIA/pipeline.py FAILED
------------------------------------------------------------
Failures:
  <NO_OTHER_FAILURES>
------------------------------------------------------------
Root Cause (first observed failure):
[0]:
  time      : 2024-09-16_15:22:29
  host      : node-05.bender
  rank      : 0 (local_rank: 0)
  exitcode  : 1 (pid: 2285761)
  error_file: <N/A>
  traceback : To enable traceback see: https://pytorch.org/docs/stable/elastic/errors.html
============================================================
srun: error: node-05: task 0: Exited with exit code 1
